<mujoco>
	<compiler autolimits="true" eulerseq="XYZ"/>
	<contact>
        <exclude name="exclude_bounding_box" body1="link3" body2="bounding box"/>
		<exclude name="exclude_bounding_box1" body1="link4" body2="bounding box"/>
		<exclude name="exclude_bounding_box2" body1="link2" body2="bounding box"/>
	</contact>

	<worldbody>
		
        <light diffuse=".5 .5 .5" pos="0 0 3" dir="0 0 -2"/>
		<geom type="plane" size="2 2 0.1" rgba=".9 0 0 1"/>
		<body name="base" pos="0 0 0.425" euler = "0 0 0">
			<geom type="cylinder" size=".08 0.425 " rgba="0 0 1 1" />
			<body name = "link1" pos="0 0 0.425" euler = "0 0 0">
				<joint name="1" type="hinge" pos="0 0 -.01" axis="0 0 1" limited= "true" range= "-180 180"/>
				<geom type="cylinder" size=".03125 0.01 " rgba=".110 .105 .105  1" />
				<body name= "link2" pos="0 0 0.17" euler = "0 0 0">
					<joint name="2" type="hinge" pos="0 0 -0.16" axis="0 1 0" limited= "true" range= "-80 80"/>
					<geom type="cylinder" size=".02 0.16 " rgba=".1 .5 0  1" />
					<body name= "link3" pos="0 0 0.335" euler = "0 0 0">
						<joint name="3" type="hinge" pos="0 0 -0.175" axis="0 1 0" limited= "true" range= "-80 80"/>
						<geom type="cylinder" size=".02 0.175 " rgba="1 1 .5  1" />
						<body name= "link4" pos="0 0 0.305" euler = "0 0 0">
							<joint name="4" type="hinge" pos="0 0 -0.13" axis="0 1 0" limited= "true" range= "-80 80"/>
							<geom type="cylinder" size=".02 0.13 " rgba="1 0 0  1" />
							<site name="tip" size="0.02" pos="0 0 0.13"/>
						</body>	
					</body>	
				</body>		
			</body>
		</body>
		<body name="bounding box" pos="0 0.5 0.85" euler = "0 0 0">
			<geom type="box" size=".5 .2 .35" rgba="0 1 0 0.1" />
		</body>	
	</worldbody>
	<actuator>
			<motor joint="1" name="t1" gear="1" ctrllimited="true" ctrlrange="-10 10"/>
            <motor joint="2" name="t2" gear="1" ctrllimited="true" ctrlrange="-10 10"/>
            <motor joint="3" name="t3" gear="1" ctrllimited="true" ctrlrange="-10 10"/>
            <motor joint="4" name="t4" gear="1" ctrllimited="true" ctrlrange="-10 10"/>
            <!-- <motor joint="5" name="t5" gear="1" ctrllimited="true" ctrlrange="-10 10"/> -->
            <!-- <motor joint="6" name="t6" gear="1" ctrllimited="true" ctrlrange="-10 10"/>
            <motor joint="7" name="t7" gear="1" ctrllimited="true" ctrlrange="-1 1"/> --> -->
            <!-- <motor joint="8" name="t8" gear="1" ctrllimited="true" ctrlrange="-1 1"/>  --> -->
			<!-- <position name="pos1" joint="1" kp="10"/>
			<position name="pos2" joint="2" kp="10"/> -->
			<!-- <position name="pos3" joint="3" kp="10"/>
			<position name="pos4" joint="4" kp="10"/>
			<position name="pos5" joint="5" kp="10"/>
			<position name="pos6" joint="6" kp="10"/>
			<position name="pos7" joint="7" kp="10"/>
			<position name="pos8" joint="8" kp="10"/>
			<velocity name="vel1" joint="1" kv="5"/>
			<velocity name="vel2" joint="2" kv="5"/>
			<velocity name="vel3" joint="3" kv="5"/>
			<velocity name="vel4" joint="4" kv="5"/>
			<velocity name="vel5" joint="5" kv="5"/>
			<velocity name="vel6" joint="6" kv="5"/>
			<velocity name="vel7" joint="7" kv="5"/>
			<velocity name="vel8" joint="8" kv="5"/> -->
	</actuator> 
	
</mujoco>



<!-- sensor/ jointlimitfrc (*) -->