<mujoco>
	<compiler autolimits="true" eulerseq="XYZ"/>
	<option gravity= "0 0 0"/>
	<contact>
        <exclude name="exclude_bounding_box" body1="link5" body2="bounding box"/>
		<exclude name="exclude_bounding_box1" body1="link4" body2="bounding box"/>
		<exclude name="exclude_bounding_box2" body1="prismatic" body2="bounding box"/>
       
	</contact>

	<worldbody>
		
        <light diffuse=".5 .5 .5" pos="0 0 3" dir="0 0 -2"/>
		<geom type="plane" size="2 2 0.1" rgba=".9 0 0 1"/>
		<body name="base" pos="0 0 0.3365" euler = "0 0 0">
			<geom type="box" size=".2 0.125 .3365 " rgba="0.1 0.5 1 1" />
			<body name = "link1" pos="0 0 0.394" euler = "0 0 0">
				<joint name="1" type="hinge" pos="0 0 -.0575" axis="0 0 1" limited= "true" range= "-180 180" /> 
				<geom type="cylinder" size=".0625 0.0575 " rgba=".110 .105 .105  1" />
				<body name= "link2" pos="0 0 0.1025" euler = "0 0 0">
					<joint name="2" type="hinge" pos="0 0 -0.045" axis="1 0 0" limited= "true" range= "-80 80"  /> 
					<geom type="cylinder" size=".03125 0.045 " rgba=".1 .5 0  1" />
					<body name= "prismatic" pos="0 0 0.055" euler = "90 0 0">
						<joint name="3" type="slide" pos="0 0 0" axis = "0 0 -1" limited= "true" range= "0 0.438" />
						<geom type="cylinder" size=".01 0.438 " rgba="1 1 .5  1" />
						<body name= "link4" pos="0 0 -.4515 " euler = "0 0 0">
							<joint name="4" type="hinge" pos="0 -0.012 .0135" axis="0 1 0" limited= "true" range= "-80 80"/>
							<geom type="cylinder" size=".008 0.0135 " rgba="1 0 0  1" />
							<body name= "link5" pos="0 0 -.027 " euler = "0 0 0">
								<joint name="5" type="hinge" pos="-0.0135 0 0" axis="1 0 0" limited= "true" range= "-80 80"/>
								<geom type="cylinder" size=".008 0.0135 " rgba="1 0 1  1" />
								<site name="tip" size="0.008" pos="0 0 -0.0135"/>
							</body>	
						</body>	
					</body>	
				</body>		 
			</body> 
		</body>
		<body name="bounding box" pos="0 0.5 0.85" euler = "0 0 0">
			<geom type="box" size=".5 0.2 .35 " rgba="0.1 0.5 1 .1" />
			
		</body>
	</worldbody>
	<actuator>
			<motor joint="1" name="t1" gear="1" ctrllimited="true" ctrlrange="-1 1"/>
            <motor joint="2" name="t2" gear="1" ctrllimited="true" ctrlrange="-10 10"/> 
            <motor joint="3" name="t3" gear="1" ctrllimited="true" ctrlrange="-10 10"/>
            <motor joint="4" name="t4" gear="1" ctrllimited="true" ctrlrange="-1 1"/>  -->
            <motor joint="5" name="t5" gear="1" ctrllimited="true" ctrlrange="-10 10"/>
            <!-- <motor joint="6" name="t6" gear="1" ctrllimited="true" ctrlrange="-10 10"/>
            <motor joint="7" name="t7" gear="1" ctrllimited="true" ctrlrange="-1 1"/> --> -->
            <!-- <motor joint="8" name="t8" gear="1" ctrllimited="true" ctrlrange="-1 1"/>  --> -->
			<!-- <position name="pos1" joint="1" kp="10"/>
			<position name="pos2" joint="2" kp="10"/> -->
			<!-- <position name="pos3" joint="3" kp="10"/>
			<position name="pos4" joint="4" kp="10"/>
			<position name="pos5" joint="5" kp="10"/>
			<position name="pos6" joint="6" kp="10"/>
			<position name="pos7" joint="7" kp="10"/>
			<position name="pos8" joint="8" kp="10"/>
			<velocity name="vel1" joint="1" kv="5"/>
			<velocity name="vel2" joint="2" kv="5"/>
			<velocity name="vel3" joint="3" kv="5"/>
			<velocity name="vel4" joint="4" kv="5"/>
			<velocity name="vel5" joint="5" kv="5"/>
			<velocity name="vel6" joint="6" kv="5"/>
			<velocity name="vel7" joint="7" kv="5"/>
			<velocity name="vel8" joint="8" kv="5"/> -->
	</actuator> 
	
</mujoco>



<!-- sensor/ jointlimitfrc (*) -->